{
    DataVersion: 3953,
    size: [3, 8, 21],
    data: [
        {pos: [1, 0, 0], state: "tropicraft:mahogany_log{axis:y}"},
        {pos: [0, 1, 0], state: "tropicraft:mahogany_log{axis:y}"},
        {pos: [1, 1, 0], state: "minecraft:jigsaw{orientation:north_up}", nbt: {final_state: "tropicraft:mahogany_log", id: "minecraft:jigsaw", name: "minecraft:branch_connector", pool: "minecraft:empty", target: "minecraft:branch_connector"}},
        {pos: [1, 1, 1], state: "tropicraft:mahogany_log{axis:y}"},
        {pos: [1, 1, 2], state: "tropicraft:mahogany_log{axis:y}"},
        {pos: [1, 1, 3], state: "tropicraft:mahogany_log{axis:y}"},
        {pos: [2, 1, 0], state: "tropicraft:mahogany_log{axis:y}"},
        {pos: [0, 2, 1], state: "tropicraft:mahogany_log{axis:y}"},
        {pos: [0, 2, 2], state: "tropicraft:mahogany_log{axis:y}"},
        {pos: [0, 2, 3], state: "tropicraft:mahogany_log{axis:y}"},
        {pos: [1, 2, 0], state: "tropicraft:mahogany_log{axis:y}"},
        {pos: [1, 2, 1], state: "tropicraft:mahogany_log{axis:y}"},
        {pos: [1, 2, 2], state: "tropicraft:mahogany_log{axis:y}"},
        {pos: [1, 2, 3], state: "tropicraft:mahogany_log{axis:y}"},
        {pos: [1, 2, 4], state: "tropicraft:mahogany_log{axis:y}"},
        {pos: [1, 2, 5], state: "tropicraft:mahogany_log{axis:y}"},
        {pos: [1, 2, 6], state: "tropicraft:mahogany_log{axis:y}"},
        {pos: [1, 2, 7], state: "tropicraft:mahogany_log{axis:y}"},
        {pos: [2, 2, 1], state: "tropicraft:mahogany_log{axis:y}"},
        {pos: [2, 2, 2], state: "tropicraft:mahogany_log{axis:y}"},
        {pos: [2, 2, 3], state: "tropicraft:mahogany_log{axis:y}"},
        {pos: [2, 2, 10], state: "tropicraft:kapok_leaves{distance:7,persistent:false,waterlogged:false}"},
        {pos: [0, 3, 4], state: "tropicraft:mahogany_log{axis:y}"},
        {pos: [0, 3, 5], state: "tropicraft:mahogany_log{axis:y}"},
        {pos: [0, 3, 6], state: "tropicraft:mahogany_log{axis:y}"},
        {pos: [0, 3, 7], state: "tropicraft:mahogany_log{axis:y}"},
        {pos: [1, 3, 3], state: "tropicraft:mahogany_log{axis:y}"},
        {pos: [1, 3, 4], state: "tropicraft:mahogany_log{axis:y}"},
        {pos: [1, 3, 5], state: "tropicraft:mahogany_log{axis:y}"},
        {pos: [1, 3, 6], state: "tropicraft:mahogany_log{axis:y}"},
        {pos: [1, 3, 7], state: "tropicraft:mahogany_log{axis:y}"},
        {pos: [1, 3, 8], state: "tropicraft:mahogany_log{axis:y}"},
        {pos: [1, 3, 9], state: "tropicraft:mahogany_log{axis:y}"},
        {pos: [1, 3, 10], state: "tropicraft:mahogany_log{axis:y}"},
        {pos: [2, 3, 4], state: "tropicraft:mahogany_log{axis:y}"},
        {pos: [2, 3, 5], state: "tropicraft:mahogany_log{axis:y}"},
        {pos: [2, 3, 6], state: "tropicraft:mahogany_log{axis:y}"},
        {pos: [2, 3, 7], state: "tropicraft:mahogany_log{axis:y}"},
        {pos: [0, 4, 8], state: "tropicraft:mahogany_log{axis:y}"},
        {pos: [0, 4, 9], state: "tropicraft:mahogany_log{axis:y}"},
        {pos: [0, 4, 10], state: "tropicraft:mahogany_log{axis:y}"},
        {pos: [1, 4, 7], state: "tropicraft:mahogany_log{axis:y}"},
        {pos: [1, 4, 8], state: "tropicraft:mahogany_log{axis:y}"},
        {pos: [1, 4, 9], state: "tropicraft:mahogany_log{axis:y}"},
        {pos: [1, 4, 10], state: "tropicraft:mahogany_log{axis:y}"},
        {pos: [1, 4, 11], state: "tropicraft:mahogany_log{axis:y}"},
        {pos: [1, 4, 12], state: "tropicraft:mahogany_log{axis:y}"},
        {pos: [1, 4, 13], state: "tropicraft:mahogany_log{axis:y}"},
        {pos: [2, 4, 8], state: "tropicraft:mahogany_log{axis:y}"},
        {pos: [2, 4, 9], state: "tropicraft:mahogany_log{axis:y}"},
        {pos: [2, 4, 10], state: "tropicraft:mahogany_log{axis:y}"},
        {pos: [0, 5, 11], state: "tropicraft:mahogany_log{axis:y}"},
        {pos: [0, 5, 12], state: "tropicraft:mahogany_log{axis:y}"},
        {pos: [0, 5, 13], state: "tropicraft:mahogany_log{axis:y}"},
        {pos: [1, 5, 10], state: "tropicraft:mahogany_log{axis:y}"},
        {pos: [1, 5, 11], state: "tropicraft:mahogany_log{axis:y}"},
        {pos: [1, 5, 12], state: "tropicraft:mahogany_log{axis:y}"},
        {pos: [1, 5, 13], state: "tropicraft:mahogany_log{axis:y}"},
        {pos: [1, 5, 14], state: "tropicraft:mahogany_log{axis:y}"},
        {pos: [1, 5, 15], state: "tropicraft:mahogany_log{axis:y}"},
        {pos: [1, 5, 16], state: "tropicraft:mahogany_log{axis:y}"},
        {pos: [1, 5, 17], state: "tropicraft:mahogany_log{axis:y}"},
        {pos: [2, 5, 11], state: "tropicraft:mahogany_log{axis:y}"},
        {pos: [2, 5, 12], state: "tropicraft:mahogany_log{axis:y}"},
        {pos: [2, 5, 13], state: "tropicraft:mahogany_log{axis:y}"},
        {pos: [0, 6, 14], state: "tropicraft:mahogany_log{axis:y}"},
        {pos: [0, 6, 15], state: "tropicraft:mahogany_log{axis:y}"},
        {pos: [0, 6, 16], state: "tropicraft:mahogany_log{axis:y}"},
        {pos: [0, 6, 17], state: "tropicraft:mahogany_log{axis:y}"},
        {pos: [1, 6, 13], state: "tropicraft:mahogany_log{axis:y}"},
        {pos: [1, 6, 14], state: "tropicraft:mahogany_log{axis:y}"},
        {pos: [1, 6, 15], state: "tropicraft:mahogany_log{axis:y}"},
        {pos: [1, 6, 16], state: "tropicraft:mahogany_log{axis:y}"},
        {pos: [1, 6, 17], state: "tropicraft:mahogany_log{axis:y}"},
        {pos: [1, 6, 18], state: "tropicraft:mahogany_log{axis:y}"},
        {pos: [1, 6, 19], state: "tropicraft:mahogany_log{axis:y}"},
        {pos: [2, 6, 14], state: "tropicraft:mahogany_log{axis:y}"},
        {pos: [2, 6, 15], state: "tropicraft:mahogany_log{axis:y}"},
        {pos: [2, 6, 16], state: "tropicraft:mahogany_log{axis:y}"},
        {pos: [2, 6, 17], state: "tropicraft:mahogany_log{axis:y}"},
        {pos: [0, 7, 18], state: "tropicraft:mahogany_log{axis:y}"},
        {pos: [0, 7, 19], state: "tropicraft:mahogany_log{axis:y}"},
        {pos: [1, 7, 17], state: "tropicraft:mahogany_log{axis:y}"},
        {pos: [1, 7, 18], state: "tropicraft:mahogany_log{axis:y}"},
        {pos: [1, 7, 19], state: "tropicraft:mahogany_log{axis:y}"},
        {pos: [1, 7, 20], state: "tropicraft:mahogany_log{axis:y}"},
        {pos: [2, 7, 18], state: "tropicraft:mahogany_log{axis:y}"},
        {pos: [2, 7, 19], state: "tropicraft:mahogany_log{axis:y}"}
    ],
    entities: [],
    palette: [
        "tropicraft:mahogany_log{axis:y}",
        "tropicraft:kapok_leaves{distance:7,persistent:false,waterlogged:false}",
        "minecraft:jigsaw{orientation:north_up}"
    ]
}