{
    DataVersion: 3953,
    size: [17, 5, 17],
    data: [
        {pos: [0, 0, 8], state: "tropicraft:mahogany_log{axis:y}"},
        {pos: [1, 0, 5], state: "tropicraft:mahogany_log{axis:y}"},
        {pos: [1, 0, 6], state: "tropicraft:mahogany_log{axis:y}"},
        {pos: [1, 0, 7], state: "tropicraft:mahogany_log{axis:y}"},
        {pos: [1, 0, 8], state: "tropicraft:mahogany_log{axis:y}"},
        {pos: [1, 0, 9], state: "tropicraft:mahogany_log{axis:y}"},
        {pos: [1, 0, 10], state: "tropicraft:mahogany_log{axis:y}"},
        {pos: [1, 0, 11], state: "tropicraft:mahogany_log{axis:y}"},
        {pos: [2, 0, 3], state: "tropicraft:mahogany_log{axis:y}"},
        {pos: [2, 0, 4], state: "tropicraft:mahogany_log{axis:y}"},
        {pos: [2, 0, 5], state: "tropicraft:mahogany_log{axis:y}"},
        {pos: [2, 0, 6], state: "tropicraft:mahogany_log{axis:y}"},
        {pos: [2, 0, 7], state: "tropicraft:mahogany_log{axis:y}"},
        {pos: [2, 0, 8], state: "tropicraft:mahogany_log{axis:y}"},
        {pos: [2, 0, 9], state: "tropicraft:mahogany_log{axis:y}"},
        {pos: [2, 0, 10], state: "tropicraft:mahogany_log{axis:y}"},
        {pos: [2, 0, 11], state: "tropicraft:mahogany_log{axis:y}"},
        {pos: [2, 0, 12], state: "tropicraft:mahogany_log{axis:y}"},
        {pos: [2, 0, 13], state: "tropicraft:mahogany_log{axis:y}"},
        {pos: [3, 0, 2], state: "tropicraft:mahogany_log{axis:y}"},
        {pos: [3, 0, 3], state: "tropicraft:mahogany_log{axis:y}"},
        {pos: [3, 0, 4], state: "tropicraft:mahogany_log{axis:y}"},
        {pos: [3, 0, 5], state: "tropicraft:mahogany_log{axis:y}"},
        {pos: [3, 0, 6], state: "tropicraft:mahogany_log{axis:y}"},
        {pos: [3, 0, 7], state: "tropicraft:mahogany_log{axis:y}"},
        {pos: [3, 0, 8], state: "tropicraft:mahogany_log{axis:y}"},
        {pos: [3, 0, 9], state: "tropicraft:mahogany_log{axis:y}"},
        {pos: [3, 0, 10], state: "tropicraft:mahogany_log{axis:y}"},
        {pos: [3, 0, 11], state: "tropicraft:mahogany_log{axis:y}"},
        {pos: [3, 0, 12], state: "tropicraft:mahogany_log{axis:y}"},
        {pos: [3, 0, 13], state: "tropicraft:mahogany_log{axis:y}"},
        {pos: [3, 0, 14], state: "tropicraft:mahogany_log{axis:y}"},
        {pos: [4, 0, 2], state: "tropicraft:mahogany_log{axis:y}"},
        {pos: [4, 0, 3], state: "tropicraft:mahogany_log{axis:y}"},
        {pos: [4, 0, 4], state: "tropicraft:mahogany_log{axis:y}"},
        {pos: [4, 0, 5], state: "tropicraft:mahogany_log{axis:y}"},
        {pos: [4, 0, 6], state: "minecraft:air"},
        {pos: [4, 0, 7], state: "minecraft:air"},
        {pos: [4, 0, 8], state: "minecraft:air"},
        {pos: [4, 0, 9], state: "minecraft:air"},
        {pos: [4, 0, 10], state: "minecraft:air"},
        {pos: [4, 0, 11], state: "tropicraft:mahogany_log{axis:y}"},
        {pos: [4, 0, 12], state: "tropicraft:mahogany_log{axis:y}"},
        {pos: [4, 0, 13], state: "tropicraft:mahogany_log{axis:y}"},
        {pos: [4, 0, 14], state: "tropicraft:mahogany_log{axis:y}"},
        {pos: [5, 0, 1], state: "tropicraft:mahogany_log{axis:y}"},
        {pos: [5, 0, 2], state: "tropicraft:mahogany_log{axis:y}"},
        {pos: [5, 0, 3], state: "tropicraft:mahogany_log{axis:y}"},
        {pos: [5, 0, 4], state: "tropicraft:mahogany_log{axis:y}"},
        {pos: [5, 0, 5], state: "minecraft:air"},
        {pos: [5, 0, 6], state: "minecraft:air"},
        {pos: [5, 0, 7], state: "minecraft:air"},
        {pos: [5, 0, 8], state: "minecraft:air"},
        {pos: [5, 0, 9], state: "minecraft:air"},
        {pos: [5, 0, 10], state: "minecraft:air"},
        {pos: [5, 0, 11], state: "minecraft:air"},
        {pos: [5, 0, 12], state: "tropicraft:mahogany_log{axis:y}"},
        {pos: [5, 0, 13], state: "tropicraft:mahogany_log{axis:y}"},
        {pos: [5, 0, 14], state: "tropicraft:mahogany_log{axis:y}"},
        {pos: [5, 0, 15], state: "tropicraft:mahogany_log{axis:y}"},
        {pos: [6, 0, 1], state: "tropicraft:mahogany_log{axis:y}"},
        {pos: [6, 0, 2], state: "tropicraft:mahogany_log{axis:y}"},
        {pos: [6, 0, 3], state: "tropicraft:mahogany_log{axis:y}"},
        {pos: [6, 0, 4], state: "minecraft:air"},
        {pos: [6, 0, 5], state: "minecraft:air"},
        {pos: [6, 0, 6], state: "minecraft:air"},
        {pos: [6, 0, 7], state: "minecraft:air"},
        {pos: [6, 0, 8], state: "minecraft:air"},
        {pos: [6, 0, 9], state: "minecraft:air"},
        {pos: [6, 0, 10], state: "minecraft:air"},
        {pos: [6, 0, 11], state: "minecraft:air"},
        {pos: [6, 0, 12], state: "minecraft:air"},
        {pos: [6, 0, 13], state: "tropicraft:mahogany_log{axis:y}"},
        {pos: [6, 0, 14], state: "tropicraft:mahogany_log{axis:y}"},
        {pos: [6, 0, 15], state: "tropicraft:mahogany_log{axis:y}"},
        {pos: [7, 0, 1], state: "tropicraft:mahogany_log{axis:y}"},
        {pos: [7, 0, 2], state: "tropicraft:mahogany_log{axis:y}"},
        {pos: [7, 0, 3], state: "tropicraft:mahogany_log{axis:y}"},
        {pos: [7, 0, 4], state: "minecraft:air"},
        {pos: [7, 0, 5], state: "minecraft:air"},
        {pos: [7, 0, 6], state: "minecraft:air"},
        {pos: [7, 0, 7], state: "minecraft:air"},
        {pos: [7, 0, 8], state: "minecraft:vine{east:true,north:false,south:false,up:false,west:false}"},
        {pos: [7, 0, 9], state: "minecraft:air"},
        {pos: [7, 0, 10], state: "minecraft:air"},
        {pos: [7, 0, 11], state: "minecraft:air"},
        {pos: [7, 0, 12], state: "minecraft:air"},
        {pos: [7, 0, 13], state: "tropicraft:mahogany_log{axis:y}"},
        {pos: [7, 0, 14], state: "tropicraft:mahogany_log{axis:y}"},
        {pos: [7, 0, 15], state: "tropicraft:mahogany_log{axis:y}"},
        {pos: [8, 0, 0], state: "tropicraft:mahogany_log{axis:y}"},
        {pos: [8, 0, 1], state: "tropicraft:mahogany_log{axis:y}"},
        {pos: [8, 0, 2], state: "tropicraft:mahogany_log{axis:y}"},
        {pos: [8, 0, 3], state: "tropicraft:mahogany_log{axis:y}"},
        {pos: [8, 0, 4], state: "minecraft:air"},
        {pos: [8, 0, 5], state: "minecraft:air"},
        {pos: [8, 0, 6], state: "minecraft:air"},
        {pos: [8, 0, 7], state: "minecraft:vine{east:false,north:false,south:true,up:false,west:false}"},
        {pos: [8, 0, 8], state: "minecraft:jigsaw{orientation:down_south}", nbt: {final_state: "tropicraft:mahogany_log", id: "minecraft:jigsaw", name: "minecraft:top_connector", pool: "minecraft:empty", target: "minecraft:top_connector"}},
        {pos: [8, 0, 9], state: "minecraft:vine{east:false,north:true,south:false,up:false,west:false}"},
        {pos: [8, 0, 10], state: "minecraft:air"},
        {pos: [8, 0, 11], state: "minecraft:air"},
        {pos: [8, 0, 12], state: "minecraft:air"},
        {pos: [8, 0, 13], state: "tropicraft:mahogany_log{axis:y}"},
        {pos: [8, 0, 14], state: "tropicraft:mahogany_log{axis:y}"},
        {pos: [8, 0, 15], state: "tropicraft:mahogany_log{axis:y}"},
        {pos: [8, 0, 16], state: "tropicraft:mahogany_log{axis:y}"},
        {pos: [9, 0, 1], state: "tropicraft:mahogany_log{axis:y}"},
        {pos: [9, 0, 2], state: "tropicraft:mahogany_log{axis:y}"},
        {pos: [9, 0, 3], state: "tropicraft:mahogany_log{axis:y}"},
        {pos: [9, 0, 4], state: "minecraft:air"},
        {pos: [9, 0, 5], state: "minecraft:air"},
        {pos: [9, 0, 6], state: "minecraft:air"},
        {pos: [9, 0, 7], state: "minecraft:air"},
        {pos: [9, 0, 8], state: "minecraft:vine{east:false,north:false,south:false,up:false,west:true}"},
        {pos: [9, 0, 9], state: "minecraft:air"},
        {pos: [9, 0, 10], state: "minecraft:air"},
        {pos: [9, 0, 11], state: "minecraft:air"},
        {pos: [9, 0, 12], state: "minecraft:air"},
        {pos: [9, 0, 13], state: "tropicraft:mahogany_log{axis:y}"},
        {pos: [9, 0, 14], state: "tropicraft:mahogany_log{axis:y}"},
        {pos: [9, 0, 15], state: "tropicraft:mahogany_log{axis:y}"},
        {pos: [10, 0, 1], state: "tropicraft:mahogany_log{axis:y}"},
        {pos: [10, 0, 2], state: "tropicraft:mahogany_log{axis:y}"},
        {pos: [10, 0, 3], state: "tropicraft:mahogany_log{axis:y}"},
        {pos: [10, 0, 4], state: "minecraft:air"},
        {pos: [10, 0, 5], state: "minecraft:air"},
        {pos: [10, 0, 6], state: "minecraft:air"},
        {pos: [10, 0, 7], state: "minecraft:air"},
        {pos: [10, 0, 8], state: "minecraft:air"},
        {pos: [10, 0, 9], state: "minecraft:air"},
        {pos: [10, 0, 10], state: "minecraft:air"},
        {pos: [10, 0, 11], state: "minecraft:air"},
        {pos: [10, 0, 12], state: "minecraft:air"},
        {pos: [10, 0, 13], state: "tropicraft:mahogany_log{axis:y}"},
        {pos: [10, 0, 14], state: "tropicraft:mahogany_log{axis:y}"},
        {pos: [10, 0, 15], state: "tropicraft:mahogany_log{axis:y}"},
        {pos: [11, 0, 1], state: "tropicraft:mahogany_log{axis:y}"},
        {pos: [11, 0, 2], state: "tropicraft:mahogany_log{axis:y}"},
        {pos: [11, 0, 3], state: "tropicraft:mahogany_log{axis:y}"},
        {pos: [11, 0, 4], state: "tropicraft:mahogany_log{axis:y}"},
        {pos: [11, 0, 5], state: "minecraft:air"},
        {pos: [11, 0, 6], state: "minecraft:air"},
        {pos: [11, 0, 7], state: "minecraft:air"},
        {pos: [11, 0, 8], state: "minecraft:air"},
        {pos: [11, 0, 9], state: "minecraft:air"},
        {pos: [11, 0, 10], state: "minecraft:air"},
        {pos: [11, 0, 11], state: "minecraft:air"},
        {pos: [11, 0, 12], state: "tropicraft:mahogany_log{axis:y}"},
        {pos: [11, 0, 13], state: "tropicraft:mahogany_log{axis:y}"},
        {pos: [11, 0, 14], state: "tropicraft:mahogany_log{axis:y}"},
        {pos: [11, 0, 15], state: "tropicraft:mahogany_log{axis:y}"},
        {pos: [12, 0, 2], state: "tropicraft:mahogany_log{axis:y}"},
        {pos: [12, 0, 3], state: "tropicraft:mahogany_log{axis:y}"},
        {pos: [12, 0, 4], state: "tropicraft:mahogany_log{axis:y}"},
        {pos: [12, 0, 5], state: "tropicraft:mahogany_log{axis:y}"},
        {pos: [12, 0, 6], state: "minecraft:air"},
        {pos: [12, 0, 7], state: "minecraft:air"},
        {pos: [12, 0, 8], state: "minecraft:air"},
        {pos: [12, 0, 9], state: "minecraft:air"},
        {pos: [12, 0, 10], state: "minecraft:air"},
        {pos: [12, 0, 11], state: "tropicraft:mahogany_log{axis:y}"},
        {pos: [12, 0, 12], state: "tropicraft:mahogany_log{axis:y}"},
        {pos: [12, 0, 13], state: "tropicraft:mahogany_log{axis:y}"},
        {pos: [12, 0, 14], state: "tropicraft:mahogany_log{axis:y}"},
        {pos: [13, 0, 2], state: "tropicraft:mahogany_log{axis:y}"},
        {pos: [13, 0, 3], state: "tropicraft:mahogany_log{axis:y}"},
        {pos: [13, 0, 4], state: "tropicraft:mahogany_log{axis:y}"},
        {pos: [13, 0, 5], state: "tropicraft:mahogany_log{axis:y}"},
        {pos: [13, 0, 6], state: "tropicraft:mahogany_log{axis:y}"},
        {pos: [13, 0, 7], state: "tropicraft:mahogany_log{axis:y}"},
        {pos: [13, 0, 8], state: "tropicraft:mahogany_log{axis:y}"},
        {pos: [13, 0, 9], state: "tropicraft:mahogany_log{axis:y}"},
        {pos: [13, 0, 10], state: "tropicraft:mahogany_log{axis:y}"},
        {pos: [13, 0, 11], state: "tropicraft:mahogany_log{axis:y}"},
        {pos: [13, 0, 12], state: "tropicraft:mahogany_log{axis:y}"},
        {pos: [13, 0, 13], state: "tropicraft:mahogany_log{axis:y}"},
        {pos: [13, 0, 14], state: "tropicraft:mahogany_log{axis:y}"},
        {pos: [14, 0, 3], state: "tropicraft:mahogany_log{axis:y}"},
        {pos: [14, 0, 4], state: "tropicraft:mahogany_log{axis:y}"},
        {pos: [14, 0, 5], state: "tropicraft:mahogany_log{axis:y}"},
        {pos: [14, 0, 6], state: "tropicraft:mahogany_log{axis:y}"},
        {pos: [14, 0, 7], state: "tropicraft:mahogany_log{axis:y}"},
        {pos: [14, 0, 8], state: "tropicraft:mahogany_log{axis:y}"},
        {pos: [14, 0, 9], state: "tropicraft:mahogany_log{axis:y}"},
        {pos: [14, 0, 10], state: "tropicraft:mahogany_log{axis:y}"},
        {pos: [14, 0, 11], state: "tropicraft:mahogany_log{axis:y}"},
        {pos: [14, 0, 12], state: "tropicraft:mahogany_log{axis:y}"},
        {pos: [14, 0, 13], state: "tropicraft:mahogany_log{axis:y}"},
        {pos: [15, 0, 5], state: "tropicraft:mahogany_log{axis:y}"},
        {pos: [15, 0, 6], state: "tropicraft:mahogany_log{axis:y}"},
        {pos: [15, 0, 7], state: "tropicraft:mahogany_log{axis:y}"},
        {pos: [15, 0, 8], state: "tropicraft:mahogany_log{axis:y}"},
        {pos: [15, 0, 9], state: "tropicraft:mahogany_log{axis:y}"},
        {pos: [15, 0, 10], state: "tropicraft:mahogany_log{axis:y}"},
        {pos: [15, 0, 11], state: "tropicraft:mahogany_log{axis:y}"},
        {pos: [16, 0, 8], state: "tropicraft:mahogany_log{axis:y}"},
        {pos: [0, 1, 8], state: "tropicraft:mahogany_log{axis:y}"},
        {pos: [1, 1, 5], state: "tropicraft:mahogany_log{axis:y}"},
        {pos: [1, 1, 6], state: "tropicraft:mahogany_log{axis:y}"},
        {pos: [1, 1, 7], state: "tropicraft:mahogany_log{axis:y}"},
        {pos: [1, 1, 8], state: "tropicraft:mahogany_log{axis:y}"},
        {pos: [1, 1, 9], state: "tropicraft:mahogany_log{axis:y}"},
        {pos: [1, 1, 10], state: "tropicraft:mahogany_log{axis:y}"},
        {pos: [1, 1, 11], state: "tropicraft:mahogany_log{axis:y}"},
        {pos: [2, 1, 3], state: "tropicraft:mahogany_log{axis:y}"},
        {pos: [2, 1, 4], state: "tropicraft:mahogany_log{axis:y}"},
        {pos: [2, 1, 5], state: "tropicraft:mahogany_log{axis:y}"},
        {pos: [2, 1, 6], state: "tropicraft:mahogany_log{axis:y}"},
        {pos: [2, 1, 7], state: "tropicraft:mahogany_log{axis:y}"},
        {pos: [2, 1, 8], state: "tropicraft:mahogany_log{axis:y}"},
        {pos: [2, 1, 9], state: "tropicraft:mahogany_log{axis:y}"},
        {pos: [2, 1, 10], state: "tropicraft:mahogany_log{axis:y}"},
        {pos: [2, 1, 11], state: "tropicraft:mahogany_log{axis:y}"},
        {pos: [2, 1, 12], state: "tropicraft:mahogany_log{axis:y}"},
        {pos: [2, 1, 13], state: "tropicraft:mahogany_log{axis:y}"},
        {pos: [3, 1, 2], state: "tropicraft:mahogany_log{axis:y}"},
        {pos: [3, 1, 3], state: "tropicraft:mahogany_log{axis:y}"},
        {pos: [3, 1, 4], state: "tropicraft:mahogany_log{axis:y}"},
        {pos: [3, 1, 5], state: "tropicraft:mahogany_log{axis:y}"},
        {pos: [3, 1, 6], state: "tropicraft:mahogany_log{axis:y}"},
        {pos: [3, 1, 7], state: "tropicraft:mahogany_log{axis:y}"},
        {pos: [3, 1, 8], state: "tropicraft:mahogany_log{axis:y}"},
        {pos: [3, 1, 9], state: "tropicraft:mahogany_log{axis:y}"},
        {pos: [3, 1, 10], state: "tropicraft:mahogany_log{axis:y}"},
        {pos: [3, 1, 11], state: "tropicraft:mahogany_log{axis:y}"},
        {pos: [3, 1, 12], state: "tropicraft:mahogany_log{axis:y}"},
        {pos: [3, 1, 13], state: "tropicraft:mahogany_log{axis:y}"},
        {pos: [3, 1, 14], state: "tropicraft:mahogany_log{axis:y}"},
        {pos: [4, 1, 2], state: "tropicraft:mahogany_log{axis:y}"},
        {pos: [4, 1, 3], state: "tropicraft:mahogany_log{axis:y}"},
        {pos: [4, 1, 4], state: "tropicraft:mahogany_log{axis:y}"},
        {pos: [4, 1, 5], state: "tropicraft:mahogany_log{axis:y}"},
        {pos: [4, 1, 6], state: "minecraft:air"},
        {pos: [4, 1, 7], state: "minecraft:air"},
        {pos: [4, 1, 8], state: "minecraft:air"},
        {pos: [4, 1, 9], state: "minecraft:air"},
        {pos: [4, 1, 10], state: "minecraft:air"},
        {pos: [4, 1, 11], state: "tropicraft:mahogany_log{axis:y}"},
        {pos: [4, 1, 12], state: "tropicraft:mahogany_log{axis:y}"},
        {pos: [4, 1, 13], state: "tropicraft:mahogany_log{axis:y}"},
        {pos: [4, 1, 14], state: "tropicraft:mahogany_log{axis:y}"},
        {pos: [5, 1, 1], state: "tropicraft:mahogany_log{axis:y}"},
        {pos: [5, 1, 2], state: "tropicraft:mahogany_log{axis:y}"},
        {pos: [5, 1, 3], state: "tropicraft:mahogany_log{axis:y}"},
        {pos: [5, 1, 4], state: "tropicraft:mahogany_log{axis:y}"},
        {pos: [5, 1, 5], state: "minecraft:air"},
        {pos: [5, 1, 6], state: "minecraft:air"},
        {pos: [5, 1, 7], state: "minecraft:air"},
        {pos: [5, 1, 8], state: "minecraft:air"},
        {pos: [5, 1, 9], state: "minecraft:air"},
        {pos: [5, 1, 10], state: "minecraft:air"},
        {pos: [5, 1, 11], state: "minecraft:air"},
        {pos: [5, 1, 12], state: "tropicraft:mahogany_log{axis:y}"},
        {pos: [5, 1, 13], state: "tropicraft:mahogany_log{axis:y}"},
        {pos: [5, 1, 14], state: "tropicraft:mahogany_log{axis:y}"},
        {pos: [5, 1, 15], state: "tropicraft:mahogany_log{axis:y}"},
        {pos: [6, 1, 1], state: "tropicraft:mahogany_log{axis:y}"},
        {pos: [6, 1, 2], state: "tropicraft:mahogany_log{axis:y}"},
        {pos: [6, 1, 3], state: "tropicraft:mahogany_log{axis:y}"},
        {pos: [6, 1, 4], state: "minecraft:air"},
        {pos: [6, 1, 5], state: "minecraft:air"},
        {pos: [6, 1, 6], state: "minecraft:air"},
        {pos: [6, 1, 7], state: "minecraft:air"},
        {pos: [6, 1, 8], state: "minecraft:air"},
        {pos: [6, 1, 9], state: "minecraft:air"},
        {pos: [6, 1, 10], state: "minecraft:air"},
        {pos: [6, 1, 11], state: "minecraft:air"},
        {pos: [6, 1, 12], state: "minecraft:air"},
        {pos: [6, 1, 13], state: "tropicraft:mahogany_log{axis:y}"},
        {pos: [6, 1, 14], state: "tropicraft:mahogany_log{axis:y}"},
        {pos: [6, 1, 15], state: "tropicraft:mahogany_log{axis:y}"},
        {pos: [7, 1, 1], state: "tropicraft:mahogany_log{axis:y}"},
        {pos: [7, 1, 2], state: "tropicraft:mahogany_log{axis:y}"},
        {pos: [7, 1, 3], state: "tropicraft:mahogany_log{axis:y}"},
        {pos: [7, 1, 4], state: "minecraft:air"},
        {pos: [7, 1, 5], state: "minecraft:air"},
        {pos: [7, 1, 6], state: "minecraft:air"},
        {pos: [7, 1, 7], state: "minecraft:air"},
        {pos: [7, 1, 8], state: "minecraft:vine{east:true,north:false,south:false,up:false,west:false}"},
        {pos: [7, 1, 9], state: "minecraft:air"},
        {pos: [7, 1, 10], state: "minecraft:air"},
        {pos: [7, 1, 11], state: "minecraft:air"},
        {pos: [7, 1, 12], state: "minecraft:air"},
        {pos: [7, 1, 13], state: "tropicraft:mahogany_log{axis:y}"},
        {pos: [7, 1, 14], state: "tropicraft:mahogany_log{axis:y}"},
        {pos: [7, 1, 15], state: "tropicraft:mahogany_log{axis:y}"},
        {pos: [8, 1, 0], state: "tropicraft:mahogany_log{axis:y}"},
        {pos: [8, 1, 1], state: "tropicraft:mahogany_log{axis:y}"},
        {pos: [8, 1, 2], state: "tropicraft:mahogany_log{axis:y}"},
        {pos: [8, 1, 3], state: "tropicraft:mahogany_log{axis:y}"},
        {pos: [8, 1, 4], state: "minecraft:air"},
        {pos: [8, 1, 5], state: "minecraft:air"},
        {pos: [8, 1, 6], state: "minecraft:air"},
        {pos: [8, 1, 7], state: "minecraft:vine{east:false,north:false,south:true,up:false,west:false}"},
        {pos: [8, 1, 8], state: "tropicraft:mahogany_log{axis:y}"},
        {pos: [8, 1, 9], state: "minecraft:vine{east:false,north:true,south:false,up:false,west:false}"},
        {pos: [8, 1, 10], state: "minecraft:air"},
        {pos: [8, 1, 11], state: "minecraft:air"},
        {pos: [8, 1, 12], state: "minecraft:air"},
        {pos: [8, 1, 13], state: "tropicraft:mahogany_log{axis:y}"},
        {pos: [8, 1, 14], state: "tropicraft:mahogany_log{axis:y}"},
        {pos: [8, 1, 15], state: "tropicraft:mahogany_log{axis:y}"},
        {pos: [8, 1, 16], state: "tropicraft:mahogany_log{axis:y}"},
        {pos: [9, 1, 1], state: "tropicraft:mahogany_log{axis:y}"},
        {pos: [9, 1, 2], state: "tropicraft:mahogany_log{axis:y}"},
        {pos: [9, 1, 3], state: "tropicraft:mahogany_log{axis:y}"},
        {pos: [9, 1, 4], state: "minecraft:air"},
        {pos: [9, 1, 5], state: "minecraft:air"},
        {pos: [9, 1, 6], state: "minecraft:air"},
        {pos: [9, 1, 7], state: "minecraft:air"},
        {pos: [9, 1, 8], state: "minecraft:vine{east:false,north:false,south:false,up:false,west:true}"},
        {pos: [9, 1, 9], state: "minecraft:air"},
        {pos: [9, 1, 10], state: "minecraft:air"},
        {pos: [9, 1, 11], state: "minecraft:air"},
        {pos: [9, 1, 12], state: "minecraft:air"},
        {pos: [9, 1, 13], state: "tropicraft:mahogany_log{axis:y}"},
        {pos: [9, 1, 14], state: "tropicraft:mahogany_log{axis:y}"},
        {pos: [9, 1, 15], state: "tropicraft:mahogany_log{axis:y}"},
        {pos: [10, 1, 1], state: "tropicraft:mahogany_log{axis:y}"},
        {pos: [10, 1, 2], state: "tropicraft:mahogany_log{axis:y}"},
        {pos: [10, 1, 3], state: "tropicraft:mahogany_log{axis:y}"},
        {pos: [10, 1, 4], state: "minecraft:air"},
        {pos: [10, 1, 5], state: "minecraft:air"},
        {pos: [10, 1, 6], state: "minecraft:air"},
        {pos: [10, 1, 7], state: "minecraft:air"},
        {pos: [10, 1, 8], state: "minecraft:air"},
        {pos: [10, 1, 9], state: "minecraft:air"},
        {pos: [10, 1, 10], state: "minecraft:air"},
        {pos: [10, 1, 11], state: "minecraft:air"},
        {pos: [10, 1, 12], state: "minecraft:air"},
        {pos: [10, 1, 13], state: "tropicraft:mahogany_log{axis:y}"},
        {pos: [10, 1, 14], state: "tropicraft:mahogany_log{axis:y}"},
        {pos: [10, 1, 15], state: "tropicraft:mahogany_log{axis:y}"},
        {pos: [11, 1, 1], state: "tropicraft:mahogany_log{axis:y}"},
        {pos: [11, 1, 2], state: "tropicraft:mahogany_log{axis:y}"},
        {pos: [11, 1, 3], state: "tropicraft:mahogany_log{axis:y}"},
        {pos: [11, 1, 4], state: "tropicraft:mahogany_log{axis:y}"},
        {pos: [11, 1, 5], state: "minecraft:air"},
        {pos: [11, 1, 6], state: "minecraft:air"},
        {pos: [11, 1, 7], state: "minecraft:air"},
        {pos: [11, 1, 8], state: "minecraft:air"},
        {pos: [11, 1, 9], state: "minecraft:air"},
        {pos: [11, 1, 10], state: "minecraft:air"},
        {pos: [11, 1, 11], state: "minecraft:air"},
        {pos: [11, 1, 12], state: "tropicraft:mahogany_log{axis:y}"},
        {pos: [11, 1, 13], state: "tropicraft:mahogany_log{axis:y}"},
        {pos: [11, 1, 14], state: "tropicraft:mahogany_log{axis:y}"},
        {pos: [11, 1, 15], state: "tropicraft:mahogany_log{axis:y}"},
        {pos: [12, 1, 2], state: "tropicraft:mahogany_log{axis:y}"},
        {pos: [12, 1, 3], state: "tropicraft:mahogany_log{axis:y}"},
        {pos: [12, 1, 4], state: "tropicraft:mahogany_log{axis:y}"},
        {pos: [12, 1, 5], state: "tropicraft:mahogany_log{axis:y}"},
        {pos: [12, 1, 6], state: "minecraft:air"},
        {pos: [12, 1, 7], state: "minecraft:air"},
        {pos: [12, 1, 8], state: "minecraft:air"},
        {pos: [12, 1, 9], state: "minecraft:air"},
        {pos: [12, 1, 10], state: "minecraft:air"},
        {pos: [12, 1, 11], state: "tropicraft:mahogany_log{axis:y}"},
        {pos: [12, 1, 12], state: "tropicraft:mahogany_log{axis:y}"},
        {pos: [12, 1, 13], state: "tropicraft:mahogany_log{axis:y}"},
        {pos: [12, 1, 14], state: "tropicraft:mahogany_log{axis:y}"},
        {pos: [13, 1, 2], state: "tropicraft:mahogany_log{axis:y}"},
        {pos: [13, 1, 3], state: "tropicraft:mahogany_log{axis:y}"},
        {pos: [13, 1, 4], state: "tropicraft:mahogany_log{axis:y}"},
        {pos: [13, 1, 5], state: "tropicraft:mahogany_log{axis:y}"},
        {pos: [13, 1, 6], state: "tropicraft:mahogany_log{axis:y}"},
        {pos: [13, 1, 7], state: "tropicraft:mahogany_log{axis:y}"},
        {pos: [13, 1, 8], state: "tropicraft:mahogany_log{axis:y}"},
        {pos: [13, 1, 9], state: "tropicraft:mahogany_log{axis:y}"},
        {pos: [13, 1, 10], state: "tropicraft:mahogany_log{axis:y}"},
        {pos: [13, 1, 11], state: "tropicraft:mahogany_log{axis:y}"},
        {pos: [13, 1, 12], state: "tropicraft:mahogany_log{axis:y}"},
        {pos: [13, 1, 13], state: "tropicraft:mahogany_log{axis:y}"},
        {pos: [13, 1, 14], state: "tropicraft:mahogany_log{axis:y}"},
        {pos: [14, 1, 3], state: "tropicraft:mahogany_log{axis:y}"},
        {pos: [14, 1, 4], state: "tropicraft:mahogany_log{axis:y}"},
        {pos: [14, 1, 5], state: "tropicraft:mahogany_log{axis:y}"},
        {pos: [14, 1, 6], state: "tropicraft:mahogany_log{axis:y}"},
        {pos: [14, 1, 7], state: "tropicraft:mahogany_log{axis:y}"},
        {pos: [14, 1, 8], state: "tropicraft:mahogany_log{axis:y}"},
        {pos: [14, 1, 9], state: "tropicraft:mahogany_log{axis:y}"},
        {pos: [14, 1, 10], state: "tropicraft:mahogany_log{axis:y}"},
        {pos: [14, 1, 11], state: "tropicraft:mahogany_log{axis:y}"},
        {pos: [14, 1, 12], state: "tropicraft:mahogany_log{axis:y}"},
        {pos: [14, 1, 13], state: "tropicraft:mahogany_log{axis:y}"},
        {pos: [15, 1, 5], state: "tropicraft:mahogany_log{axis:y}"},
        {pos: [15, 1, 6], state: "tropicraft:mahogany_log{axis:y}"},
        {pos: [15, 1, 7], state: "tropicraft:mahogany_log{axis:y}"},
        {pos: [15, 1, 8], state: "tropicraft:mahogany_log{axis:y}"},
        {pos: [15, 1, 9], state: "tropicraft:mahogany_log{axis:y}"},
        {pos: [15, 1, 10], state: "tropicraft:mahogany_log{axis:y}"},
        {pos: [15, 1, 11], state: "tropicraft:mahogany_log{axis:y}"},
        {pos: [16, 1, 8], state: "tropicraft:mahogany_log{axis:y}"},
        {pos: [0, 2, 8], state: "tropicraft:mahogany_log{axis:y}"},
        {pos: [1, 2, 5], state: "tropicraft:mahogany_log{axis:y}"},
        {pos: [1, 2, 6], state: "tropicraft:mahogany_log{axis:y}"},
        {pos: [1, 2, 7], state: "tropicraft:mahogany_log{axis:y}"},
        {pos: [1, 2, 8], state: "tropicraft:mahogany_log{axis:y}"},
        {pos: [1, 2, 9], state: "tropicraft:mahogany_log{axis:y}"},
        {pos: [1, 2, 10], state: "tropicraft:mahogany_log{axis:y}"},
        {pos: [1, 2, 11], state: "tropicraft:mahogany_log{axis:y}"},
        {pos: [2, 2, 3], state: "tropicraft:mahogany_log{axis:y}"},
        {pos: [2, 2, 4], state: "tropicraft:mahogany_log{axis:y}"},
        {pos: [2, 2, 5], state: "tropicraft:mahogany_log{axis:y}"},
        {pos: [2, 2, 6], state: "tropicraft:mahogany_log{axis:y}"},
        {pos: [2, 2, 7], state: "tropicraft:mahogany_log{axis:y}"},
        {pos: [2, 2, 8], state: "tropicraft:mahogany_log{axis:y}"},
        {pos: [2, 2, 9], state: "tropicraft:mahogany_log{axis:y}"},
        {pos: [2, 2, 10], state: "tropicraft:mahogany_log{axis:y}"},
        {pos: [2, 2, 11], state: "tropicraft:mahogany_log{axis:y}"},
        {pos: [2, 2, 12], state: "tropicraft:mahogany_log{axis:y}"},
        {pos: [2, 2, 13], state: "tropicraft:mahogany_log{axis:y}"},
        {pos: [3, 2, 2], state: "tropicraft:mahogany_log{axis:y}"},
        {pos: [3, 2, 3], state: "tropicraft:mahogany_log{axis:y}"},
        {pos: [3, 2, 4], state: "tropicraft:mahogany_log{axis:y}"},
        {pos: [3, 2, 5], state: "tropicraft:mahogany_log{axis:y}"},
        {pos: [3, 2, 6], state: "tropicraft:mahogany_log{axis:y}"},
        {pos: [3, 2, 7], state: "tropicraft:mahogany_log{axis:y}"},
        {pos: [3, 2, 8], state: "tropicraft:mahogany_log{axis:y}"},
        {pos: [3, 2, 9], state: "tropicraft:mahogany_log{axis:y}"},
        {pos: [3, 2, 10], state: "tropicraft:mahogany_log{axis:y}"},
        {pos: [3, 2, 11], state: "tropicraft:mahogany_log{axis:y}"},
        {pos: [3, 2, 12], state: "tropicraft:mahogany_log{axis:y}"},
        {pos: [3, 2, 13], state: "tropicraft:mahogany_log{axis:y}"},
        {pos: [3, 2, 14], state: "tropicraft:mahogany_log{axis:y}"},
        {pos: [4, 2, 2], state: "tropicraft:mahogany_log{axis:y}"},
        {pos: [4, 2, 3], state: "tropicraft:mahogany_log{axis:y}"},
        {pos: [4, 2, 4], state: "tropicraft:mahogany_log{axis:y}"},
        {pos: [4, 2, 5], state: "tropicraft:mahogany_log{axis:y}"},
        {pos: [4, 2, 6], state: "minecraft:air"},
        {pos: [4, 2, 7], state: "minecraft:air"},
        {pos: [4, 2, 8], state: "minecraft:air"},
        {pos: [4, 2, 9], state: "minecraft:air"},
        {pos: [4, 2, 10], state: "minecraft:air"},
        {pos: [4, 2, 11], state: "tropicraft:mahogany_log{axis:y}"},
        {pos: [4, 2, 12], state: "tropicraft:mahogany_log{axis:y}"},
        {pos: [4, 2, 13], state: "tropicraft:mahogany_log{axis:y}"},
        {pos: [4, 2, 14], state: "tropicraft:mahogany_log{axis:y}"},
        {pos: [5, 2, 1], state: "tropicraft:mahogany_log{axis:y}"},
        {pos: [5, 2, 2], state: "tropicraft:mahogany_log{axis:y}"},
        {pos: [5, 2, 3], state: "tropicraft:mahogany_log{axis:y}"},
        {pos: [5, 2, 4], state: "tropicraft:mahogany_log{axis:y}"},
        {pos: [5, 2, 5], state: "minecraft:air"},
        {pos: [5, 2, 6], state: "minecraft:air"},
        {pos: [5, 2, 7], state: "minecraft:air"},
        {pos: [5, 2, 8], state: "minecraft:air"},
        {pos: [5, 2, 9], state: "minecraft:air"},
        {pos: [5, 2, 10], state: "minecraft:air"},
        {pos: [5, 2, 11], state: "minecraft:air"},
        {pos: [5, 2, 12], state: "tropicraft:mahogany_log{axis:y}"},
        {pos: [5, 2, 13], state: "tropicraft:mahogany_log{axis:y}"},
        {pos: [5, 2, 14], state: "tropicraft:mahogany_log{axis:y}"},
        {pos: [5, 2, 15], state: "tropicraft:mahogany_log{axis:y}"},
        {pos: [6, 2, 1], state: "tropicraft:mahogany_log{axis:y}"},
        {pos: [6, 2, 2], state: "tropicraft:mahogany_log{axis:y}"},
        {pos: [6, 2, 3], state: "tropicraft:mahogany_log{axis:y}"},
        {pos: [6, 2, 4], state: "minecraft:air"},
        {pos: [6, 2, 5], state: "minecraft:air"},
        {pos: [6, 2, 6], state: "minecraft:air"},
        {pos: [6, 2, 7], state: "minecraft:air"},
        {pos: [6, 2, 8], state: "minecraft:air"},
        {pos: [6, 2, 9], state: "minecraft:air"},
        {pos: [6, 2, 10], state: "minecraft:air"},
        {pos: [6, 2, 11], state: "minecraft:air"},
        {pos: [6, 2, 12], state: "minecraft:air"},
        {pos: [6, 2, 13], state: "tropicraft:mahogany_log{axis:y}"},
        {pos: [6, 2, 14], state: "tropicraft:mahogany_log{axis:y}"},
        {pos: [6, 2, 15], state: "tropicraft:mahogany_log{axis:y}"},
        {pos: [7, 2, 1], state: "tropicraft:mahogany_log{axis:y}"},
        {pos: [7, 2, 2], state: "tropicraft:mahogany_log{axis:y}"},
        {pos: [7, 2, 3], state: "tropicraft:mahogany_log{axis:y}"},
        {pos: [7, 2, 4], state: "minecraft:air"},
        {pos: [7, 2, 5], state: "minecraft:air"},
        {pos: [7, 2, 6], state: "minecraft:air"},
        {pos: [7, 2, 7], state: "minecraft:air"},
        {pos: [7, 2, 8], state: "minecraft:vine{east:true,north:false,south:false,up:false,west:false}"},
        {pos: [7, 2, 9], state: "minecraft:air"},
        {pos: [7, 2, 10], state: "minecraft:air"},
        {pos: [7, 2, 11], state: "minecraft:air"},
        {pos: [7, 2, 12], state: "minecraft:air"},
        {pos: [7, 2, 13], state: "tropicraft:mahogany_log{axis:y}"},
        {pos: [7, 2, 14], state: "tropicraft:mahogany_log{axis:y}"},
        {pos: [7, 2, 15], state: "tropicraft:mahogany_log{axis:y}"},
        {pos: [8, 2, 0], state: "tropicraft:mahogany_log{axis:y}"},
        {pos: [8, 2, 1], state: "tropicraft:mahogany_log{axis:y}"},
        {pos: [8, 2, 2], state: "tropicraft:mahogany_log{axis:y}"},
        {pos: [8, 2, 3], state: "tropicraft:mahogany_log{axis:y}"},
        {pos: [8, 2, 4], state: "minecraft:air"},
        {pos: [8, 2, 5], state: "minecraft:air"},
        {pos: [8, 2, 6], state: "minecraft:air"},
        {pos: [8, 2, 7], state: "minecraft:vine{east:false,north:false,south:true,up:false,west:false}"},
        {pos: [8, 2, 8], state: "tropicraft:mahogany_log{axis:y}"},
        {pos: [8, 2, 9], state: "minecraft:vine{east:false,north:true,south:false,up:false,west:false}"},
        {pos: [8, 2, 10], state: "minecraft:air"},
        {pos: [8, 2, 11], state: "minecraft:air"},
        {pos: [8, 2, 12], state: "minecraft:air"},
        {pos: [8, 2, 13], state: "tropicraft:mahogany_log{axis:y}"},
        {pos: [8, 2, 14], state: "tropicraft:mahogany_log{axis:y}"},
        {pos: [8, 2, 15], state: "tropicraft:mahogany_log{axis:y}"},
        {pos: [8, 2, 16], state: "tropicraft:mahogany_log{axis:y}"},
        {pos: [9, 2, 1], state: "tropicraft:mahogany_log{axis:y}"},
        {pos: [9, 2, 2], state: "tropicraft:mahogany_log{axis:y}"},
        {pos: [9, 2, 3], state: "tropicraft:mahogany_log{axis:y}"},
        {pos: [9, 2, 4], state: "minecraft:air"},
        {pos: [9, 2, 5], state: "minecraft:air"},
        {pos: [9, 2, 6], state: "minecraft:air"},
        {pos: [9, 2, 7], state: "minecraft:air"},
        {pos: [9, 2, 8], state: "minecraft:vine{east:false,north:false,south:false,up:false,west:true}"},
        {pos: [9, 2, 9], state: "minecraft:air"},
        {pos: [9, 2, 10], state: "minecraft:air"},
        {pos: [9, 2, 11], state: "minecraft:air"},
        {pos: [9, 2, 12], state: "minecraft:air"},
        {pos: [9, 2, 13], state: "tropicraft:mahogany_log{axis:y}"},
        {pos: [9, 2, 14], state: "tropicraft:mahogany_log{axis:y}"},
        {pos: [9, 2, 15], state: "tropicraft:mahogany_log{axis:y}"},
        {pos: [10, 2, 1], state: "tropicraft:mahogany_log{axis:y}"},
        {pos: [10, 2, 2], state: "tropicraft:mahogany_log{axis:y}"},
        {pos: [10, 2, 3], state: "tropicraft:mahogany_log{axis:y}"},
        {pos: [10, 2, 4], state: "minecraft:air"},
        {pos: [10, 2, 5], state: "minecraft:air"},
        {pos: [10, 2, 6], state: "minecraft:air"},
        {pos: [10, 2, 7], state: "minecraft:air"},
        {pos: [10, 2, 8], state: "minecraft:air"},
        {pos: [10, 2, 9], state: "minecraft:air"},
        {pos: [10, 2, 10], state: "minecraft:air"},
        {pos: [10, 2, 11], state: "minecraft:air"},
        {pos: [10, 2, 12], state: "minecraft:air"},
        {pos: [10, 2, 13], state: "tropicraft:mahogany_log{axis:y}"},
        {pos: [10, 2, 14], state: "tropicraft:mahogany_log{axis:y}"},
        {pos: [10, 2, 15], state: "tropicraft:mahogany_log{axis:y}"},
        {pos: [11, 2, 1], state: "tropicraft:mahogany_log{axis:y}"},
        {pos: [11, 2, 2], state: "tropicraft:mahogany_log{axis:y}"},
        {pos: [11, 2, 3], state: "tropicraft:mahogany_log{axis:y}"},
        {pos: [11, 2, 4], state: "tropicraft:mahogany_log{axis:y}"},
        {pos: [11, 2, 5], state: "minecraft:air"},
        {pos: [11, 2, 6], state: "minecraft:air"},
        {pos: [11, 2, 7], state: "minecraft:air"},
        {pos: [11, 2, 8], state: "minecraft:air"},
        {pos: [11, 2, 9], state: "minecraft:air"},
        {pos: [11, 2, 10], state: "minecraft:air"},
        {pos: [11, 2, 11], state: "minecraft:air"},
        {pos: [11, 2, 12], state: "tropicraft:mahogany_log{axis:y}"},
        {pos: [11, 2, 13], state: "tropicraft:mahogany_log{axis:y}"},
        {pos: [11, 2, 14], state: "tropicraft:mahogany_log{axis:y}"},
        {pos: [11, 2, 15], state: "tropicraft:mahogany_log{axis:y}"},
        {pos: [12, 2, 2], state: "tropicraft:mahogany_log{axis:y}"},
        {pos: [12, 2, 3], state: "tropicraft:mahogany_log{axis:y}"},
        {pos: [12, 2, 4], state: "tropicraft:mahogany_log{axis:y}"},
        {pos: [12, 2, 5], state: "tropicraft:mahogany_log{axis:y}"},
        {pos: [12, 2, 6], state: "minecraft:air"},
        {pos: [12, 2, 7], state: "minecraft:air"},
        {pos: [12, 2, 8], state: "minecraft:air"},
        {pos: [12, 2, 9], state: "minecraft:air"},
        {pos: [12, 2, 10], state: "minecraft:air"},
        {pos: [12, 2, 11], state: "tropicraft:mahogany_log{axis:y}"},
        {pos: [12, 2, 12], state: "tropicraft:mahogany_log{axis:y}"},
        {pos: [12, 2, 13], state: "tropicraft:mahogany_log{axis:y}"},
        {pos: [12, 2, 14], state: "tropicraft:mahogany_log{axis:y}"},
        {pos: [13, 2, 2], state: "tropicraft:mahogany_log{axis:y}"},
        {pos: [13, 2, 3], state: "tropicraft:mahogany_log{axis:y}"},
        {pos: [13, 2, 4], state: "tropicraft:mahogany_log{axis:y}"},
        {pos: [13, 2, 5], state: "tropicraft:mahogany_log{axis:y}"},
        {pos: [13, 2, 6], state: "tropicraft:mahogany_log{axis:y}"},
        {pos: [13, 2, 7], state: "tropicraft:mahogany_log{axis:y}"},
        {pos: [13, 2, 8], state: "tropicraft:mahogany_log{axis:y}"},
        {pos: [13, 2, 9], state: "tropicraft:mahogany_log{axis:y}"},
        {pos: [13, 2, 10], state: "tropicraft:mahogany_log{axis:y}"},
        {pos: [13, 2, 11], state: "tropicraft:mahogany_log{axis:y}"},
        {pos: [13, 2, 12], state: "tropicraft:mahogany_log{axis:y}"},
        {pos: [13, 2, 13], state: "tropicraft:mahogany_log{axis:y}"},
        {pos: [13, 2, 14], state: "tropicraft:mahogany_log{axis:y}"},
        {pos: [14, 2, 3], state: "tropicraft:mahogany_log{axis:y}"},
        {pos: [14, 2, 4], state: "tropicraft:mahogany_log{axis:y}"},
        {pos: [14, 2, 5], state: "tropicraft:mahogany_log{axis:y}"},
        {pos: [14, 2, 6], state: "tropicraft:mahogany_log{axis:y}"},
        {pos: [14, 2, 7], state: "tropicraft:mahogany_log{axis:y}"},
        {pos: [14, 2, 8], state: "tropicraft:mahogany_log{axis:y}"},
        {pos: [14, 2, 9], state: "tropicraft:mahogany_log{axis:y}"},
        {pos: [14, 2, 10], state: "tropicraft:mahogany_log{axis:y}"},
        {pos: [14, 2, 11], state: "tropicraft:mahogany_log{axis:y}"},
        {pos: [14, 2, 12], state: "tropicraft:mahogany_log{axis:y}"},
        {pos: [14, 2, 13], state: "tropicraft:mahogany_log{axis:y}"},
        {pos: [15, 2, 5], state: "tropicraft:mahogany_log{axis:y}"},
        {pos: [15, 2, 6], state: "tropicraft:mahogany_log{axis:y}"},
        {pos: [15, 2, 7], state: "tropicraft:mahogany_log{axis:y}"},
        {pos: [15, 2, 8], state: "tropicraft:mahogany_log{axis:y}"},
        {pos: [15, 2, 9], state: "tropicraft:mahogany_log{axis:y}"},
        {pos: [15, 2, 10], state: "tropicraft:mahogany_log{axis:y}"},
        {pos: [15, 2, 11], state: "tropicraft:mahogany_log{axis:y}"},
        {pos: [16, 2, 8], state: "tropicraft:mahogany_log{axis:y}"},
        {pos: [0, 3, 8], state: "tropicraft:mahogany_log{axis:y}"},
        {pos: [1, 3, 5], state: "tropicraft:mahogany_log{axis:y}"},
        {pos: [1, 3, 6], state: "tropicraft:mahogany_log{axis:y}"},
        {pos: [1, 3, 7], state: "tropicraft:mahogany_log{axis:y}"},
        {pos: [1, 3, 8], state: "tropicraft:mahogany_log{axis:y}"},
        {pos: [1, 3, 9], state: "tropicraft:mahogany_log{axis:y}"},
        {pos: [1, 3, 10], state: "tropicraft:mahogany_log{axis:y}"},
        {pos: [1, 3, 11], state: "tropicraft:mahogany_log{axis:y}"},
        {pos: [2, 3, 3], state: "tropicraft:mahogany_log{axis:y}"},
        {pos: [2, 3, 4], state: "tropicraft:mahogany_log{axis:y}"},
        {pos: [2, 3, 5], state: "tropicraft:mahogany_log{axis:y}"},
        {pos: [2, 3, 6], state: "tropicraft:mahogany_log{axis:y}"},
        {pos: [2, 3, 7], state: "tropicraft:mahogany_log{axis:y}"},
        {pos: [2, 3, 8], state: "tropicraft:mahogany_log{axis:y}"},
        {pos: [2, 3, 9], state: "tropicraft:mahogany_log{axis:y}"},
        {pos: [2, 3, 10], state: "tropicraft:mahogany_log{axis:y}"},
        {pos: [2, 3, 11], state: "tropicraft:mahogany_log{axis:y}"},
        {pos: [2, 3, 12], state: "tropicraft:mahogany_log{axis:y}"},
        {pos: [2, 3, 13], state: "tropicraft:mahogany_log{axis:y}"},
        {pos: [3, 3, 2], state: "tropicraft:mahogany_log{axis:y}"},
        {pos: [3, 3, 3], state: "tropicraft:mahogany_log{axis:y}"},
        {pos: [3, 3, 4], state: "tropicraft:mahogany_log{axis:y}"},
        {pos: [3, 3, 5], state: "tropicraft:mahogany_log{axis:y}"},
        {pos: [3, 3, 6], state: "tropicraft:mahogany_log{axis:y}"},
        {pos: [3, 3, 7], state: "tropicraft:mahogany_log{axis:y}"},
        {pos: [3, 3, 8], state: "tropicraft:mahogany_log{axis:y}"},
        {pos: [3, 3, 9], state: "tropicraft:mahogany_log{axis:y}"},
        {pos: [3, 3, 10], state: "tropicraft:mahogany_log{axis:y}"},
        {pos: [3, 3, 11], state: "tropicraft:mahogany_log{axis:y}"},
        {pos: [3, 3, 12], state: "tropicraft:mahogany_log{axis:y}"},
        {pos: [3, 3, 13], state: "tropicraft:mahogany_log{axis:y}"},
        {pos: [3, 3, 14], state: "tropicraft:mahogany_log{axis:y}"},
        {pos: [4, 3, 2], state: "tropicraft:mahogany_log{axis:y}"},
        {pos: [4, 3, 3], state: "tropicraft:mahogany_log{axis:y}"},
        {pos: [4, 3, 4], state: "tropicraft:mahogany_log{axis:y}"},
        {pos: [4, 3, 5], state: "tropicraft:mahogany_log{axis:y}"},
        {pos: [4, 3, 6], state: "tropicraft:mahogany_log{axis:y}"},
        {pos: [4, 3, 7], state: "tropicraft:mahogany_log{axis:y}"},
        {pos: [4, 3, 8], state: "tropicraft:mahogany_log{axis:y}"},
        {pos: [4, 3, 9], state: "tropicraft:mahogany_log{axis:y}"},
        {pos: [4, 3, 10], state: "tropicraft:mahogany_log{axis:y}"},
        {pos: [4, 3, 11], state: "tropicraft:mahogany_log{axis:y}"},
        {pos: [4, 3, 12], state: "tropicraft:mahogany_log{axis:y}"},
        {pos: [4, 3, 13], state: "tropicraft:mahogany_log{axis:y}"},
        {pos: [4, 3, 14], state: "tropicraft:mahogany_log{axis:y}"},
        {pos: [5, 3, 1], state: "tropicraft:mahogany_log{axis:y}"},
        {pos: [5, 3, 2], state: "tropicraft:mahogany_log{axis:y}"},
        {pos: [5, 3, 3], state: "tropicraft:mahogany_log{axis:y}"},
        {pos: [5, 3, 4], state: "tropicraft:mahogany_log{axis:y}"},
        {pos: [5, 3, 5], state: "tropicraft:mahogany_log{axis:y}"},
        {pos: [5, 3, 6], state: "tropicraft:mahogany_log{axis:y}"},
        {pos: [5, 3, 7], state: "tropicraft:mahogany_log{axis:y}"},
        {pos: [5, 3, 8], state: "tropicraft:mahogany_log{axis:y}"},
        {pos: [5, 3, 9], state: "tropicraft:mahogany_log{axis:y}"},
        {pos: [5, 3, 10], state: "tropicraft:mahogany_log{axis:y}"},
        {pos: [5, 3, 11], state: "tropicraft:mahogany_log{axis:y}"},
        {pos: [5, 3, 12], state: "tropicraft:mahogany_log{axis:y}"},
        {pos: [5, 3, 13], state: "tropicraft:mahogany_log{axis:y}"},
        {pos: [5, 3, 14], state: "tropicraft:mahogany_log{axis:y}"},
        {pos: [5, 3, 15], state: "tropicraft:mahogany_log{axis:y}"},
        {pos: [6, 3, 1], state: "tropicraft:mahogany_log{axis:y}"},
        {pos: [6, 3, 2], state: "tropicraft:mahogany_log{axis:y}"},
        {pos: [6, 3, 3], state: "tropicraft:mahogany_log{axis:y}"},
        {pos: [6, 3, 4], state: "tropicraft:mahogany_log{axis:y}"},
        {pos: [6, 3, 5], state: "tropicraft:mahogany_log{axis:y}"},
        {pos: [6, 3, 6], state: "tropicraft:mahogany_log{axis:y}"},
        {pos: [6, 3, 7], state: "tropicraft:mahogany_log{axis:y}"},
        {pos: [6, 3, 8], state: "tropicraft:mahogany_log{axis:y}"},
        {pos: [6, 3, 9], state: "tropicraft:mahogany_log{axis:y}"},
        {pos: [6, 3, 10], state: "tropicraft:mahogany_log{axis:y}"},
        {pos: [6, 3, 11], state: "tropicraft:mahogany_log{axis:y}"},
        {pos: [6, 3, 12], state: "tropicraft:mahogany_log{axis:y}"},
        {pos: [6, 3, 13], state: "tropicraft:mahogany_log{axis:y}"},
        {pos: [6, 3, 14], state: "tropicraft:mahogany_log{axis:y}"},
        {pos: [6, 3, 15], state: "tropicraft:mahogany_log{axis:y}"},
        {pos: [7, 3, 1], state: "tropicraft:mahogany_log{axis:y}"},
        {pos: [7, 3, 2], state: "tropicraft:mahogany_log{axis:y}"},
        {pos: [7, 3, 3], state: "tropicraft:mahogany_log{axis:y}"},
        {pos: [7, 3, 4], state: "tropicraft:mahogany_log{axis:y}"},
        {pos: [7, 3, 5], state: "tropicraft:mahogany_log{axis:y}"},
        {pos: [7, 3, 6], state: "tropicraft:mahogany_log{axis:y}"},
        {pos: [7, 3, 7], state: "tropicraft:mahogany_log{axis:y}"},
        {pos: [7, 3, 8], state: "minecraft:vine{east:true,north:false,south:false,up:false,west:false}"},
        {pos: [7, 3, 9], state: "tropicraft:mahogany_log{axis:y}"},
        {pos: [7, 3, 10], state: "tropicraft:mahogany_log{axis:y}"},
        {pos: [7, 3, 11], state: "tropicraft:mahogany_log{axis:y}"},
        {pos: [7, 3, 12], state: "tropicraft:mahogany_log{axis:y}"},
        {pos: [7, 3, 13], state: "tropicraft:mahogany_log{axis:y}"},
        {pos: [7, 3, 14], state: "tropicraft:mahogany_log{axis:y}"},
        {pos: [7, 3, 15], state: "tropicraft:mahogany_log{axis:y}"},
        {pos: [8, 3, 0], state: "tropicraft:mahogany_log{axis:y}"},
        {pos: [8, 3, 1], state: "tropicraft:mahogany_log{axis:y}"},
        {pos: [8, 3, 2], state: "tropicraft:mahogany_log{axis:y}"},
        {pos: [8, 3, 3], state: "tropicraft:mahogany_log{axis:y}"},
        {pos: [8, 3, 4], state: "tropicraft:mahogany_log{axis:y}"},
        {pos: [8, 3, 5], state: "tropicraft:mahogany_log{axis:y}"},
        {pos: [8, 3, 6], state: "tropicraft:mahogany_log{axis:y}"},
        {pos: [8, 3, 7], state: "minecraft:vine{east:false,north:false,south:true,up:false,west:false}"},
        {pos: [8, 3, 8], state: "tropicraft:mahogany_log{axis:y}"},
        {pos: [8, 3, 9], state: "minecraft:vine{east:false,north:true,south:false,up:false,west:false}"},
        {pos: [8, 3, 10], state: "tropicraft:mahogany_log{axis:y}"},
        {pos: [8, 3, 11], state: "tropicraft:mahogany_log{axis:y}"},
        {pos: [8, 3, 12], state: "tropicraft:mahogany_log{axis:y}"},
        {pos: [8, 3, 13], state: "tropicraft:mahogany_log{axis:y}"},
        {pos: [8, 3, 14], state: "tropicraft:mahogany_log{axis:y}"},
        {pos: [8, 3, 15], state: "tropicraft:mahogany_log{axis:y}"},
        {pos: [8, 3, 16], state: "tropicraft:mahogany_log{axis:y}"},
        {pos: [9, 3, 1], state: "tropicraft:mahogany_log{axis:y}"},
        {pos: [9, 3, 2], state: "tropicraft:mahogany_log{axis:y}"},
        {pos: [9, 3, 3], state: "tropicraft:mahogany_log{axis:y}"},
        {pos: [9, 3, 4], state: "tropicraft:mahogany_log{axis:y}"},
        {pos: [9, 3, 5], state: "tropicraft:mahogany_log{axis:y}"},
        {pos: [9, 3, 6], state: "tropicraft:mahogany_log{axis:y}"},
        {pos: [9, 3, 7], state: "tropicraft:mahogany_log{axis:y}"},
        {pos: [9, 3, 8], state: "minecraft:vine{east:false,north:false,south:false,up:false,west:true}"},
        {pos: [9, 3, 9], state: "tropicraft:mahogany_log{axis:y}"},
        {pos: [9, 3, 10], state: "tropicraft:mahogany_log{axis:y}"},
        {pos: [9, 3, 11], state: "tropicraft:mahogany_log{axis:y}"},
        {pos: [9, 3, 12], state: "tropicraft:mahogany_log{axis:y}"},
        {pos: [9, 3, 13], state: "tropicraft:mahogany_log{axis:y}"},
        {pos: [9, 3, 14], state: "tropicraft:mahogany_log{axis:y}"},
        {pos: [9, 3, 15], state: "tropicraft:mahogany_log{axis:y}"},
        {pos: [10, 3, 1], state: "tropicraft:mahogany_log{axis:y}"},
        {pos: [10, 3, 2], state: "tropicraft:mahogany_log{axis:y}"},
        {pos: [10, 3, 3], state: "tropicraft:mahogany_log{axis:y}"},
        {pos: [10, 3, 4], state: "tropicraft:mahogany_log{axis:y}"},
        {pos: [10, 3, 5], state: "tropicraft:mahogany_log{axis:y}"},
        {pos: [10, 3, 6], state: "tropicraft:mahogany_log{axis:y}"},
        {pos: [10, 3, 7], state: "tropicraft:mahogany_log{axis:y}"},
        {pos: [10, 3, 8], state: "tropicraft:mahogany_log{axis:y}"},
        {pos: [10, 3, 9], state: "tropicraft:mahogany_log{axis:y}"},
        {pos: [10, 3, 10], state: "tropicraft:mahogany_log{axis:y}"},
        {pos: [10, 3, 11], state: "tropicraft:mahogany_log{axis:y}"},
        {pos: [10, 3, 12], state: "tropicraft:mahogany_log{axis:y}"},
        {pos: [10, 3, 13], state: "tropicraft:mahogany_log{axis:y}"},
        {pos: [10, 3, 14], state: "tropicraft:mahogany_log{axis:y}"},
        {pos: [10, 3, 15], state: "tropicraft:mahogany_log{axis:y}"},
        {pos: [11, 3, 1], state: "tropicraft:mahogany_log{axis:y}"},
        {pos: [11, 3, 2], state: "tropicraft:mahogany_log{axis:y}"},
        {pos: [11, 3, 3], state: "tropicraft:mahogany_log{axis:y}"},
        {pos: [11, 3, 4], state: "tropicraft:mahogany_log{axis:y}"},
        {pos: [11, 3, 5], state: "tropicraft:mahogany_log{axis:y}"},
        {pos: [11, 3, 6], state: "tropicraft:mahogany_log{axis:y}"},
        {pos: [11, 3, 7], state: "tropicraft:mahogany_log{axis:y}"},
        {pos: [11, 3, 8], state: "tropicraft:mahogany_log{axis:y}"},
        {pos: [11, 3, 9], state: "tropicraft:mahogany_log{axis:y}"},
        {pos: [11, 3, 10], state: "tropicraft:mahogany_log{axis:y}"},
        {pos: [11, 3, 11], state: "tropicraft:mahogany_log{axis:y}"},
        {pos: [11, 3, 12], state: "tropicraft:mahogany_log{axis:y}"},
        {pos: [11, 3, 13], state: "tropicraft:mahogany_log{axis:y}"},
        {pos: [11, 3, 14], state: "tropicraft:mahogany_log{axis:y}"},
        {pos: [11, 3, 15], state: "tropicraft:mahogany_log{axis:y}"},
        {pos: [12, 3, 2], state: "tropicraft:mahogany_log{axis:y}"},
        {pos: [12, 3, 3], state: "tropicraft:mahogany_log{axis:y}"},
        {pos: [12, 3, 4], state: "tropicraft:mahogany_log{axis:y}"},
        {pos: [12, 3, 5], state: "tropicraft:mahogany_log{axis:y}"},
        {pos: [12, 3, 6], state: "tropicraft:mahogany_log{axis:y}"},
        {pos: [12, 3, 7], state: "tropicraft:mahogany_log{axis:y}"},
        {pos: [12, 3, 8], state: "tropicraft:mahogany_log{axis:y}"},
        {pos: [12, 3, 9], state: "tropicraft:mahogany_log{axis:y}"},
        {pos: [12, 3, 10], state: "tropicraft:mahogany_log{axis:y}"},
        {pos: [12, 3, 11], state: "tropicraft:mahogany_log{axis:y}"},
        {pos: [12, 3, 12], state: "tropicraft:mahogany_log{axis:y}"},
        {pos: [12, 3, 13], state: "tropicraft:mahogany_log{axis:y}"},
        {pos: [12, 3, 14], state: "tropicraft:mahogany_log{axis:y}"},
        {pos: [13, 3, 2], state: "tropicraft:mahogany_log{axis:y}"},
        {pos: [13, 3, 3], state: "tropicraft:mahogany_log{axis:y}"},
        {pos: [13, 3, 4], state: "tropicraft:mahogany_log{axis:y}"},
        {pos: [13, 3, 5], state: "tropicraft:mahogany_log{axis:y}"},
        {pos: [13, 3, 6], state: "tropicraft:mahogany_log{axis:y}"},
        {pos: [13, 3, 7], state: "tropicraft:mahogany_log{axis:y}"},
        {pos: [13, 3, 8], state: "tropicraft:mahogany_log{axis:y}"},
        {pos: [13, 3, 9], state: "tropicraft:mahogany_log{axis:y}"},
        {pos: [13, 3, 10], state: "tropicraft:mahogany_log{axis:y}"},
        {pos: [13, 3, 11], state: "tropicraft:mahogany_log{axis:y}"},
        {pos: [13, 3, 12], state: "tropicraft:mahogany_log{axis:y}"},
        {pos: [13, 3, 13], state: "tropicraft:mahogany_log{axis:y}"},
        {pos: [13, 3, 14], state: "tropicraft:mahogany_log{axis:y}"},
        {pos: [14, 3, 3], state: "tropicraft:mahogany_log{axis:y}"},
        {pos: [14, 3, 4], state: "tropicraft:mahogany_log{axis:y}"},
        {pos: [14, 3, 5], state: "tropicraft:mahogany_log{axis:y}"},
        {pos: [14, 3, 6], state: "tropicraft:mahogany_log{axis:y}"},
        {pos: [14, 3, 7], state: "tropicraft:mahogany_log{axis:y}"},
        {pos: [14, 3, 8], state: "tropicraft:mahogany_log{axis:y}"},
        {pos: [14, 3, 9], state: "tropicraft:mahogany_log{axis:y}"},
        {pos: [14, 3, 10], state: "tropicraft:mahogany_log{axis:y}"},
        {pos: [14, 3, 11], state: "tropicraft:mahogany_log{axis:y}"},
        {pos: [14, 3, 12], state: "tropicraft:mahogany_log{axis:y}"},
        {pos: [14, 3, 13], state: "tropicraft:mahogany_log{axis:y}"},
        {pos: [15, 3, 5], state: "tropicraft:mahogany_log{axis:y}"},
        {pos: [15, 3, 6], state: "tropicraft:mahogany_log{axis:y}"},
        {pos: [15, 3, 7], state: "tropicraft:mahogany_log{axis:y}"},
        {pos: [15, 3, 8], state: "tropicraft:mahogany_log{axis:y}"},
        {pos: [15, 3, 9], state: "tropicraft:mahogany_log{axis:y}"},
        {pos: [15, 3, 10], state: "tropicraft:mahogany_log{axis:y}"},
        {pos: [15, 3, 11], state: "tropicraft:mahogany_log{axis:y}"},
        {pos: [16, 3, 8], state: "tropicraft:mahogany_log{axis:y}"},
        {pos: [6, 4, 10], state: "tropicraft:bamboo_chest{facing:north,type:single,waterlogged:false}", nbt: {LootTable: "tropicraft:home_tree", id: "tropicraft:bamboo_chest", unbreakable: 0b}},
        {pos: [8, 4, 10], state: "minecraft:air"}
    ],
    entities: [],
    palette: [
        "tropicraft:mahogany_log{axis:y}",
        "minecraft:air",
        "minecraft:vine{east:true,north:false,south:false,up:false,west:false}",
        "minecraft:vine{east:false,north:false,south:true,up:false,west:false}",
        "minecraft:vine{east:false,north:true,south:false,up:false,west:false}",
        "minecraft:vine{east:false,north:false,south:false,up:false,west:true}",
        "minecraft:jigsaw{orientation:down_south}",
        "tropicraft:bamboo_chest{facing:north,type:single,waterlogged:false}"
    ]
}